{
  "version": 8,
  "blockIdVersion": 11,
  "anchorX": 0,
  "anchorY": 0,
  "anchorZ": 0,
  "blocks": [
    {
      "x": -1,
      "y": 0,
      "z": -1,
      "name": "Rock_Calcite_Brick_Half",
      "rotation": 8
    },
    {
      "x": -1,
      "y": 1,
      "z": -1,
      "name": "Rock_Calcite_Brick_Decorative"
    },
    {
      "x": -1,
      "y": 2,
      "z": -1,
      "name": "Rock_Calcite_Brick_Decorative"
    },
    {
      "x": -1,
      "y": 3,
      "z": -1,
      "name": "Rock_Calcite_Brick_Decorative"
    },
    {
      "x": -1,
      "y": 4,
      "z": -1,
      "name": "Rock_Calcite_Brick_Half"
    },
    {
      "x": -1,
      "y": 5,
      "z": -1,
      "name": "Rock_Calcite_Brick_Half",
      "rotation": 8
    },
    {
      "x": -1,
      "y": 0,
      "z": 0,
      "name": "Rock_Calcite_Brick_Half",
      "rotation": 8
    },
    {
      "x": -1,
      "y": 1,
      "z": 0,
      "name": "Furniture_Temple_Dark_Window",
      "rotation": 1
    },
    {
      "x": -1,
      "y": 2,
      "z": 0,
      "name": "Furniture_Temple_Dark_Window",
      "rotation": 1
    },
    {
      "x": -1,
      "y": 3,
      "z": 0,
      "name": "Furniture_Temple_Dark_Window",
      "rotation": 1
    },
    {
      "x": -1,
      "y": 4,
      "z": 0,
      "name": "Rock_Calcite_Brick_Half"
    },
    {
      "x": -1,
      "y": 5,
      "z": 0,
      "name": "Rock_Calcite_Brick_Half",
      "rotation": 8
    },
    {
      "x": -1,
      "y": 0,
      "z": 1,
      "name": "Rock_Calcite_Brick_Half",
      "rotation": 8
    },
    {
      "x": -1,
      "y": 1,
      "z": 1,
      "name": "Furniture_Temple_Dark_Window",
      "rotation": 1
    },
    {
      "x": -1,
      "y": 2,
      "z": 1,
      "name": "Furniture_Temple_Dark_Window",
      "rotation": 1
    },
    {
      "x": -1,
      "y": 3,
      "z": 1,
      "name": "Furniture_Temple_Dark_Window",
      "rotation": 1
    },
    {
      "x": -1,
      "y": 4,
      "z": 1,
      "name": "Rock_Calcite_Brick_Half"
    },
    {
      "x": -1,
      "y": 5,
      "z": 1,
      "name": "Rock_Calcite_Brick_Half",
      "rotation": 8
    },
    {
      "x": -1,
      "y": 0,
      "z": 2,
      "name": "Rock_Calcite_Brick_Half",
      "rotation": 8
    },
    {
      "x": -1,
      "y": 1,
      "z": 2,
      "name": "Rock_Calcite_Brick_Decorative"
    },
    {
      "x": -1,
      "y": 2,
      "z": 2,
      "name": "Rock_Calcite_Brick_Decorative"
    },
    {
      "x": -1,
      "y": 3,
      "z": 2,
      "name": "Rock_Calcite_Brick_Decorative"
    },
    {
      "x": -1,
      "y": 4,
      "z": 2,
      "name": "Rock_Calcite_Brick_Half"
    },
    {
      "x": -1,
      "y": 5,
      "z": 2,
      "name": "Rock_Calcite_Brick_Half",
      "rotation": 8
    },
    {
      "x": 0,
      "y": 0,
      "z": -1,
      "name": "Rock_Calcite_Brick_Half",
      "rotation": 8
    },
    {
      "x": 0,
      "y": 1,
      "z": -1,
      "name": "Furniture_Temple_Dark_Window"
    },
    {
      "x": 0,
      "y": 2,
      "z": -1,
      "name": "Furniture_Temple_Dark_Window"
    },
    {
      "x": 0,
      "y": 3,
      "z": -1,
      "name": "Furniture_Temple_Dark_Window"
    },
    {
      "x": 0,
      "y": 4,
      "z": -1,
      "name": "Rock_Calcite_Brick_Half"
    },
    {
      "x": 0,
      "y": 5,
      "z": -1,
      "name": "Rock_Calcite_Brick_Half",
      "rotation": 8
    },
    {
      "x": 0,
      "y": 0,
      "z": 0,
      "name": "Rock_Calcite_Brick_Half",
      "rotation": 8
    },
    {
      "x": 0,
      "y": 1,
      "z": 0,
      "name": "Build_GreyLight_Cube"
    },
    {
      "x": 0,
      "y": 2,
      "z": 0,
      "name": "Build_GreyLight_Cube"
    },
    {
      "x": 0,
      "y": 3,
      "z": 0,
      "name": "Build_GreyLight_Cube"
    },
    {
      "x": 0,
      "y": 4,
      "z": 0,
      "name": "Rock_Calcite_Brick"
    },
    {
      "x": 0,
      "y": 5,
      "z": 0,
      "name": "Rock_Calcite_Brick"
    },
    {
      "x": 0,
      "y": 0,
      "z": 1,
      "name": "Rock_Calcite_Brick_Half",
      "rotation": 8
    },
    {
      "x": 0,
      "y": 1,
      "z": 1,
      "name": "Build_GreyLight_Cube"
    },
    {
      "x": 0,
      "y": 2,
      "z": 1,
      "name": "Build_GreyLight_Cube"
    },
    {
      "x": 0,
      "y": 3,
      "z": 1,
      "name": "Build_GreyLight_Cube"
    },
    {
      "x": 0,
      "y": 4,
      "z": 1,
      "name": "Rock_Calcite_Brick"
    },
    {
      "x": 0,
      "y": 5,
      "z": 1,
      "name": "Rock_Calcite_Brick"
    },
    {
      "x": 0,
      "y": 0,
      "z": 2,
      "name": "Rock_Calcite_Brick_Half",
      "rotation": 8
    },
    {
      "x": 0,
      "y": 1,
      "z": 2,
      "name": "Furniture_Temple_Dark_Window"
    },
    {
      "x": 0,
      "y": 2,
      "z": 2,
      "name": "Furniture_Temple_Dark_Window"
    },
    {
      "x": 0,
      "y": 3,
      "z": 2,
      "name": "Furniture_Temple_Dark_Window"
    },
    {
      "x": 0,
      "y": 4,
      "z": 2,
      "name": "Rock_Calcite_Brick_Half"
    },
    {
      "x": 0,
      "y": 5,
      "z": 2,
      "name": "Rock_Calcite_Brick_Half",
      "rotation": 8
    },
    {
      "x": 1,
      "y": 0,
      "z": -1,
      "name": "Rock_Calcite_Brick_Half",
      "rotation": 8
    },
    {
      "x": 1,
      "y": 1,
      "z": -1,
      "name": "Rock_Calcite_Brick_Decorative"
    },
    {
      "x": 1,
      "y": 2,
      "z": -1,
      "name": "Rock_Calcite_Brick_Decorative"
    },
    {
      "x": 1,
      "y": 3,
      "z": -1,
      "name": "Rock_Calcite_Brick_Decorative"
    },
    {
      "x": 1,
      "y": 4,
      "z": -1,
      "name": "Rock_Calcite_Brick_Half"
    },
    {
      "x": 1,
      "y": 5,
      "z": -1,
      "name": "Rock_Calcite_Brick_Half",
      "rotation": 8
    },
    {
      "x": 1,
      "y": 0,
      "z": 0,
      "name": "Rock_Calcite_Brick_Half",
      "rotation": 8
    },
    {
      "x": 1,
      "y": 1,
      "z": 0,
      "name": "Furniture_Temple_Dark_Window",
      "rotation": 1
    },
    {
      "x": 1,
      "y": 2,
      "z": 0,
      "name": "Furniture_Temple_Dark_Window",
      "rotation": 1
    },
    {
      "x": 1,
      "y": 3,
      "z": 0,
      "name": "Furniture_Temple_Dark_Window",
      "rotation": 1
    },
    {
      "x": 1,
      "y": 4,
      "z": 0,
      "name": "Rock_Calcite_Brick_Half"
    },
    {
      "x": 1,
      "y": 5,
      "z": 0,
      "name": "Rock_Calcite_Brick_Half",
      "rotation": 8
    },
    {
      "x": 1,
      "y": 0,
      "z": 1,
      "name": "Rock_Calcite_Brick_Half",
      "rotation": 8
    },
    {
      "x": 1,
      "y": 1,
      "z": 1,
      "name": "Furniture_Temple_Dark_Window",
      "rotation": 1
    },
    {
      "x": 1,
      "y": 2,
      "z": 1,
      "name": "Furniture_Temple_Dark_Window",
      "rotation": 1
    },
    {
      "x": 1,
      "y": 3,
      "z": 1,
      "name": "Furniture_Temple_Dark_Window",
      "rotation": 1
    },
    {
      "x": 1,
      "y": 4,
      "z": 1,
      "name": "Rock_Calcite_Brick_Half"
    },
    {
      "x": 1,
      "y": 5,
      "z": 1,
      "name": "Rock_Calcite_Brick_Half",
      "rotation": 8
    },
    {
      "x": 1,
      "y": 0,
      "z": 2,
      "name": "Rock_Calcite_Brick_Half",
      "rotation": 8
    },
    {
      "x": 1,
      "y": 1,
      "z": 2,
      "name": "Rock_Calcite_Brick_Decorative"
    },
    {
      "x": 1,
      "y": 2,
      "z": 2,
      "name": "Rock_Calcite_Brick_Decorative"
    },
    {
      "x": 1,
      "y": 3,
      "z": 2,
      "name": "Rock_Calcite_Brick_Decorative"
    },
    {
      "x": 1,
      "y": 4,
      "z": 2,
      "name": "Rock_Calcite_Brick_Half"
    },
    {
      "x": 1,
      "y": 5,
      "z": 2,
      "name": "Rock_Calcite_Brick_Half",
      "rotation": 8
    }
  ],
  "fluids": [
    {
      "x": -1,
      "y": 0,
      "z": -1,
      "name": "Empty",
      "level": 0
    },
    {
      "x": -1,
      "y": 1,
      "z": -1,
      "name": "Empty",
      "level": 0
    },
    {
      "x": -1,
      "y": 2,
      "z": -1,
      "name": "Empty",
      "level": 0
    },
    {
      "x": -1,
      "y": 3,
      "z": -1,
      "name": "Empty",
      "level": 0
    },
    {
      "x": -1,
      "y": 4,
      "z": -1,
      "name": "Empty",
      "level": 0
    },
    {
      "x": -1,
      "y": 5,
      "z": -1,
      "name": "Empty",
      "level": 0
    },
    {
      "x": -1,
      "y": 0,
      "z": 0,
      "name": "Empty",
      "level": 0
    },
    {
      "x": -1,
      "y": 1,
      "z": 0,
      "name": "Empty",
      "level": 0
    },
    {
      "x": -1,
      "y": 2,
      "z": 0,
      "name": "Empty",
      "level": 0
    },
    {
      "x": -1,
      "y": 3,
      "z": 0,
      "name": "Empty",
      "level": 0
    },
    {
      "x": -1,
      "y": 4,
      "z": 0,
      "name": "Empty",
      "level": 0
    },
    {
      "x": -1,
      "y": 5,
      "z": 0,
      "name": "Empty",
      "level": 0
    },
    {
      "x": -1,
      "y": 0,
      "z": 1,
      "name": "Empty",
      "level": 0
    },
    {
      "x": -1,
      "y": 1,
      "z": 1,
      "name": "Empty",
      "level": 0
    },
    {
      "x": -1,
      "y": 2,
      "z": 1,
      "name": "Empty",
      "level": 0
    },
    {
      "x": -1,
      "y": 3,
      "z": 1,
      "name": "Empty",
      "level": 0
    },
    {
      "x": -1,
      "y": 4,
      "z": 1,
      "name": "Empty",
      "level": 0
    },
    {
      "x": -1,
      "y": 5,
      "z": 1,
      "name": "Empty",
      "level": 0
    },
    {
      "x": -1,
      "y": 0,
      "z": 2,
      "name": "Empty",
      "level": 0
    },
    {
      "x": -1,
      "y": 1,
      "z": 2,
      "name": "Empty",
      "level": 0
    },
    {
      "x": -1,
      "y": 2,
      "z": 2,
      "name": "Empty",
      "level": 0
    },
    {
      "x": -1,
      "y": 3,
      "z": 2,
      "name": "Empty",
      "level": 0
    },
    {
      "x": -1,
      "y": 4,
      "z": 2,
      "name": "Empty",
      "level": 0
    },
    {
      "x": -1,
      "y": 5,
      "z": 2,
      "name": "Empty",
      "level": 0
    },
    {
      "x": 0,
      "y": 0,
      "z": -1,
      "name": "Empty",
      "level": 0
    },
    {
      "x": 0,
      "y": 1,
      "z": -1,
      "name": "Empty",
      "level": 0
    },
    {
      "x": 0,
      "y": 2,
      "z": -1,
      "name": "Empty",
      "level": 0
    },
    {
      "x": 0,
      "y": 3,
      "z": -1,
      "name": "Empty",
      "level": 0
    },
    {
      "x": 0,
      "y": 4,
      "z": -1,
      "name": "Empty",
      "level": 0
    },
    {
      "x": 0,
      "y": 5,
      "z": -1,
      "name": "Empty",
      "level": 0
    },
    {
      "x": 0,
      "y": 0,
      "z": 0,
      "name": "Empty",
      "level": 0
    },
    {
      "x": 0,
      "y": 1,
      "z": 0,
      "name": "Empty",
      "level": 0
    },
    {
      "x": 0,
      "y": 2,
      "z": 0,
      "name": "Empty",
      "level": 0
    },
    {
      "x": 0,
      "y": 3,
      "z": 0,
      "name": "Empty",
      "level": 0
    },
    {
      "x": 0,
      "y": 4,
      "z": 0,
      "name": "Empty",
      "level": 0
    },
    {
      "x": 0,
      "y": 5,
      "z": 0,
      "name": "Empty",
      "level": 0
    },
    {
      "x": 0,
      "y": 0,
      "z": 1,
      "name": "Empty",
      "level": 0
    },
    {
      "x": 0,
      "y": 1,
      "z": 1,
      "name": "Empty",
      "level": 0
    },
    {
      "x": 0,
      "y": 2,
      "z": 1,
      "name": "Empty",
      "level": 0
    },
    {
      "x": 0,
      "y": 3,
      "z": 1,
      "name": "Empty",
      "level": 0
    },
    {
      "x": 0,
      "y": 4,
      "z": 1,
      "name": "Empty",
      "level": 0
    },
    {
      "x": 0,
      "y": 5,
      "z": 1,
      "name": "Empty",
      "level": 0
    },
    {
      "x": 0,
      "y": 0,
      "z": 2,
      "name": "Empty",
      "level": 0
    },
    {
      "x": 0,
      "y": 1,
      "z": 2,
      "name": "Empty",
      "level": 0
    },
    {
      "x": 0,
      "y": 2,
      "z": 2,
      "name": "Empty",
      "level": 0
    },
    {
      "x": 0,
      "y": 3,
      "z": 2,
      "name": "Empty",
      "level": 0
    },
    {
      "x": 0,
      "y": 4,
      "z": 2,
      "name": "Empty",
      "level": 0
    },
    {
      "x": 0,
      "y": 5,
      "z": 2,
      "name": "Empty",
      "level": 0
    },
    {
      "x": 1,
      "y": 0,
      "z": -1,
      "name": "Empty",
      "level": 0
    },
    {
      "x": 1,
      "y": 1,
      "z": -1,
      "name": "Empty",
      "level": 0
    },
    {
      "x": 1,
      "y": 2,
      "z": -1,
      "name": "Empty",
      "level": 0
    },
    {
      "x": 1,
      "y": 3,
      "z": -1,
      "name": "Empty",
      "level": 0
    },
    {
      "x": 1,
      "y": 4,
      "z": -1,
      "name": "Empty",
      "level": 0
    },
    {
      "x": 1,
      "y": 5,
      "z": -1,
      "name": "Empty",
      "level": 0
    },
    {
      "x": 1,
      "y": 0,
      "z": 0,
      "name": "Empty",
      "level": 0
    },
    {
      "x": 1,
      "y": 1,
      "z": 0,
      "name": "Empty",
      "level": 0
    },
    {
      "x": 1,
      "y": 2,
      "z": 0,
      "name": "Empty",
      "level": 0
    },
    {
      "x": 1,
      "y": 3,
      "z": 0,
      "name": "Empty",
      "level": 0
    },
    {
      "x": 1,
      "y": 4,
      "z": 0,
      "name": "Empty",
      "level": 0
    },
    {
      "x": 1,
      "y": 5,
      "z": 0,
      "name": "Empty",
      "level": 0
    },
    {
      "x": 1,
      "y": 0,
      "z": 1,
      "name": "Empty",
      "level": 0
    },
    {
      "x": 1,
      "y": 1,
      "z": 1,
      "name": "Empty",
      "level": 0
    },
    {
      "x": 1,
      "y": 2,
      "z": 1,
      "name": "Empty",
      "level": 0
    },
    {
      "x": 1,
      "y": 3,
      "z": 1,
      "name": "Empty",
      "level": 0
    },
    {
      "x": 1,
      "y": 4,
      "z": 1,
      "name": "Empty",
      "level": 0
    },
    {
      "x": 1,
      "y": 5,
      "z": 1,
      "name": "Empty",
      "level": 0
    },
    {
      "x": 1,
      "y": 0,
      "z": 2,
      "name": "Empty",
      "level": 0
    },
    {
      "x": 1,
      "y": 1,
      "z": 2,
      "name": "Empty",
      "level": 0
    },
    {
      "x": 1,
      "y": 2,
      "z": 2,
      "name": "Empty",
      "level": 0
    },
    {
      "x": 1,
      "y": 3,
      "z": 2,
      "name": "Empty",
      "level": 0
    },
    {
      "x": 1,
      "y": 4,
      "z": 2,
      "name": "Empty",
      "level": 0
    },
    {
      "x": 1,
      "y": 5,
      "z": 2,
      "name": "Empty",
      "level": 0
    }
  ],
  "entities": [
    {
      "Components": {
        "Transform": {
          "Position": {
            "X": 0.5,
            "Y": 2.5,
            "Z": 1.0
          },
          "Rotation": {
            "Pitch": 0.0,
            "Yaw": 0.0,
            "Roll": 0.0
          }
        },
        "TriggerVolume": {
          "Shape": {
            "Type": "Box",
            "Min": {
              "X": -0.5,
              "Y": -1.5,
              "Z": -1.0
            },
            "Max": {
              "X": 0.5,
              "Y": 1.5,
              "Z": 1.0
            }
          },
          "Effects": [
            {
              "Type": "ReplaceBlockType",
              "Event": "TAG_ADDED",
              "Interval": 0.0,
              "Delay": 0.0,
              "FromBlockTypes": [
                "Build_GreyLight_Cube"
              ],
              "ToBlockType": "Build_Lightsource_White",
              "Bounds": "Shape",
              "X": 0.0,
              "Y": 0.0,
              "Z": 0.0,
              "Offset": {
                "X": 0.0,
                "Y": 0.0,
                "Z": 0.0
              }
            },
            {
              "Type": "PlaySound",
              "Event": "TAG_ADDED",
              "Interval": 0.0,
              "Delay": 0.0,
              "SoundEvent": "SFX_Capture_Crate_Spawn_Succeed",
              "Volume": 1.0,
              "Pitch": 1.2999999523162842
            },
            {
              "Type": "PlayVfx",
              "Event": "TAG_ADDED",
              "Interval": 0.0,
              "Delay": 0.0,
              "ParticleSystem": "Aura_Heal",
              "Offset": {
                "X": 0.0,
                "Y": -3.0,
                "Z": 0.0
              },
              "AtEntity": false,
              "Scale": 2.0,
              "Rotation": {
                "X": 0.0,
                "Y": 0.0,
                "Z": 0.0
              },
              "Duration": 3.0
            }
          ],
          "Enabled": true,
          "TargetTypes": [
            "Player"
          ],
          "Tags": {
            "Puzzle2_Lights": "Empty"
          },
          "KeepLoaded": false,
          "PrefabIndex": 0
        }
      }
    }
  ]
}